<?xml version="1.0"?>
<robot name="rob_quadrado">
  <link name="world">
    <!-- Link invisível para raiz -->
  </link>

  <joint name="world_to_base" type="fixed">
    <parent link="world"/>
    <child link="base_link"/>
    <origin xyz="0 0 0" rpy="0 0 0"/>
  </joint>

  <link name="base_link">
    <visual>
      <geometry>
        <box size="0.5 0.5 0.5"/>
      </geometry> 
      <material name="red">
        <color rgba="1 0 1 1"/>
      </material>
    </visual>	
  </link>

  <link name="base_link2">
    <visual>
      <geometry>
        <box size="1.5 1.5 0.5"/>
      </geometry>
    </visual>
    <collision>
      <geometry>
        <box size="1.5 1.5 0.5"/>
      </geometry>
    </collision>
    <inertial>
      <mass value="1.0"/>
      <origin xyz="0 0 0" rpy="0 0 0"/>
      <inertia ixx="0.02" ixy="0" ixz="0" iyy="0.02" iyz="0" izz="0.02"/>
    </inertial>
  </link>

  <link name="aaa">
    <visual>
      <geometry>
        <cylinder length="1" radius="0.02"/>
      </geometry>
    </visual>
    <collision>
      <geometry>
        <cylinder length="1" radius="0.02"/>
      </geometry>
    </collision>
    <inertial>
      <mass value="0.1"/>
      <origin xyz="0 0 0" rpy="0 0 0"/>
      <inertia ixx="0.0001" ixy="0" ixz="0" iyy="0.0001" iyz="0" izz="0.0001"/>
    </inertial>
  </link>

  <joint name="base_joint_" type="fixed">
    <parent link="base_link"/>
    <child link="base_link2"/>
    <origin xyz="1 1 0" rpy="0 0 0"/>
  </joint>

  <joint name="base_to_arm" type="revolute">
    <parent link="base_link2"/>
    <child link="aaa"/>
    <origin xyz="0 0 0" rpy="0 0 0"/>
    <axis xyz="0 1 0"/>
    <limit lower="-3.14" upper="3.14" effort="10" velocity="1"/>
  </joint>
</robot>
